[2024-07-17T09:49:54.772+0000] {taskinstance.py:991} DEBUG - previous_execution_date was called
[2024-07-17T09:49:54.789+0000] {__init__.py:54} DEBUG - Loading core task runner: StandardTaskRunner
[2024-07-17T09:49:54.802+0000] {taskinstance.py:991} DEBUG - previous_execution_date was called
[2024-07-17T09:49:54.805+0000] {base_task_runner.py:72} DEBUG - Planning to run as the  user
[2024-07-17T09:49:54.832+0000] {taskinstance.py:1988} DEBUG - <TaskInstance: hive_etl.load_data_into_hive manual__2024-07-17T09:49:17.873510+00:00 [queued]> dependency 'Task Instance State' PASSED: True, Task state queued was valid.
[2024-07-17T09:49:54.843+0000] {taskinstance.py:1988} DEBUG - <TaskInstance: hive_etl.load_data_into_hive manual__2024-07-17T09:49:17.873510+00:00 [queued]> dependency 'Previous Dagrun State' PASSED: True, The task did not have depends_on_past set.
[2024-07-17T09:49:54.843+0000] {taskinstance.py:1988} DEBUG - <TaskInstance: hive_etl.load_data_into_hive manual__2024-07-17T09:49:17.873510+00:00 [queued]> dependency 'Task Instance Not Running' PASSED: True, Task is not in running state.
[2024-07-17T09:49:54.844+0000] {taskinstance.py:1988} DEBUG - <TaskInstance: hive_etl.load_data_into_hive manual__2024-07-17T09:49:17.873510+00:00 [queued]> dependency 'Not In Retry Period' PASSED: True, The task instance was not marked for retrying.
[2024-07-17T09:49:54.844+0000] {taskinstance.py:1979} INFO - Dependencies all met for dep_context=non-requeueable deps ti=<TaskInstance: hive_etl.load_data_into_hive manual__2024-07-17T09:49:17.873510+00:00 [queued]>
[2024-07-17T09:49:54.853+0000] {taskinstance.py:1988} DEBUG - <TaskInstance: hive_etl.load_data_into_hive manual__2024-07-17T09:49:17.873510+00:00 [queued]> dependency 'Previous Dagrun State' PASSED: True, The task did not have depends_on_past set.
[2024-07-17T09:49:54.863+0000] {taskinstance.py:1988} DEBUG - <TaskInstance: hive_etl.load_data_into_hive manual__2024-07-17T09:49:17.873510+00:00 [queued]> dependency 'Pool Slots Available' PASSED: True, There are enough open slots in default_pool to execute the task
[2024-07-17T09:49:54.863+0000] {taskinstance.py:1988} DEBUG - <TaskInstance: hive_etl.load_data_into_hive manual__2024-07-17T09:49:17.873510+00:00 [queued]> dependency 'Task Concurrency' PASSED: True, Task concurrency is not set.
[2024-07-17T09:49:54.863+0000] {taskinstance.py:1988} DEBUG - <TaskInstance: hive_etl.load_data_into_hive manual__2024-07-17T09:49:17.873510+00:00 [queued]> dependency 'Not In Retry Period' PASSED: True, The task instance was not marked for retrying.
[2024-07-17T09:49:54.863+0000] {taskinstance.py:1979} INFO - Dependencies all met for dep_context=requeueable deps ti=<TaskInstance: hive_etl.load_data_into_hive manual__2024-07-17T09:49:17.873510+00:00 [queued]>
[2024-07-17T09:49:54.864+0000] {taskinstance.py:2193} INFO - Starting attempt 1 of 2
[2024-07-17T09:49:54.881+0000] {taskinstance.py:2214} INFO - Executing <Task(PythonOperator): load_data_into_hive> on 2024-07-17 09:49:17.873510+00:00
[2024-07-17T09:49:54.890+0000] {standard_task_runner.py:60} INFO - Started process 467 to run task
[2024-07-17T09:49:54.894+0000] {standard_task_runner.py:87} INFO - Running: ['***', 'tasks', 'run', 'hive_etl', 'load_data_into_hive', 'manual__2024-07-17T09:49:17.873510+00:00', '--job-id', '1924', '--raw', '--subdir', 'DAGS_FOLDER/new.py', '--cfg-path', '/tmp/tmpq5wb2cvm']
[2024-07-17T09:49:54.896+0000] {standard_task_runner.py:88} INFO - Job 1924: Subtask load_data_into_hive
[2024-07-17T09:49:54.898+0000] {cli_action_loggers.py:67} DEBUG - Calling callbacks: [<function default_action_log at 0x7a4457f56f80>]
[2024-07-17T09:49:54.968+0000] {taskinstance.py:991} DEBUG - previous_execution_date was called
[2024-07-17T09:49:54.974+0000] {task_command.py:423} INFO - Running <TaskInstance: hive_etl.load_data_into_hive manual__2024-07-17T09:49:17.873510+00:00 [running]> on host d0d849f06491
[2024-07-17T09:49:54.975+0000] {settings.py:386} DEBUG - Disposing DB connection pool (PID 467)
[2024-07-17T09:49:54.976+0000] {settings.py:249} DEBUG - Setting up DB connection pool (PID 467)
[2024-07-17T09:49:54.976+0000] {settings.py:318} DEBUG - settings.prepare_engine_args(): Using NullPool
[2024-07-17T09:49:55.031+0000] {taskinstance.py:991} DEBUG - previous_execution_date was called
[2024-07-17T09:49:55.033+0000] {taskinstance.py:1769} DEBUG - Clearing XCom data
[2024-07-17T09:49:55.039+0000] {retries.py:93} DEBUG - Running RenderedTaskInstanceFields.write with retries. Try 1 of 3
[2024-07-17T09:49:55.079+0000] {retries.py:93} DEBUG - Running RenderedTaskInstanceFields._do_delete_old_records with retries. Try 1 of 3
[2024-07-17T09:49:55.101+0000] {taskinstance.py:2510} INFO - Exporting env vars: AIRFLOW_CTX_DAG_OWNER='***' AIRFLOW_CTX_DAG_ID='hive_etl' AIRFLOW_CTX_TASK_ID='load_data_into_hive' AIRFLOW_CTX_EXECUTION_DATE='2024-07-17T09:49:17.873510+00:00' AIRFLOW_CTX_TRY_NUMBER='1' AIRFLOW_CTX_DAG_RUN_ID='manual__2024-07-17T09:49:17.873510+00:00'
[2024-07-17T09:49:55.102+0000] {__init__.py:115} DEBUG - Preparing lineage inlets and outlets
[2024-07-17T09:49:55.105+0000] {__init__.py:154} DEBUG - inlets: [], outlets: []
[2024-07-17T09:49:55.255+0000] {hive.py:609} DEBUG - TOpenSessionResp(status=TStatus(statusCode=0, infoMessages=None, sqlState=None, errorCode=None, errorMessage=None), serverProtocolVersion=5, sessionHandle=TSessionHandle(sessionId=THandleIdentifier(guid=b'\xaam\xc7\x9a\x96\xccNt\xaf03\x9d6\x85R\x15', secret=b'~D\xe4]\xbc\xeb@\xbf\x95\xaeC\xc0DI\xe6\x15')), configuration={'hive.server2.thrift.resultset.default.fetch.size': '1000'})
[2024-07-17T09:49:55.255+0000] {hive.py:475} INFO - USE `default`
[2024-07-17T09:49:55.256+0000] {hive.py:479} DEBUG - TExecuteStatementReq(sessionHandle=TSessionHandle(sessionId=THandleIdentifier(guid=b'\xaam\xc7\x9a\x96\xccNt\xaf03\x9d6\x85R\x15', secret=b'~D\xe4]\xbc\xeb@\xbf\x95\xaeC\xc0DI\xe6\x15')), statement='USE `default`', confOverlay=None, runAsync=False, queryTimeout=0)
[2024-07-17T09:49:55.376+0000] {hive.py:609} DEBUG - TExecuteStatementResp(status=TStatus(statusCode=0, infoMessages=None, sqlState=None, errorCode=None, errorMessage=None), operationHandle=TOperationHandle(operationId=THandleIdentifier(guid=b'\xbf\xe5(mD\x85D\xd1\xa6\x05\xfeS\x9f_\xdc\x00', secret=b'|\xb9\xd9\x01\xaf\xfeLK\x81\xe7\x0c\xcf\x83\xd6$\x1f'), operationType=0, hasResultSet=False, modifiedRowCount=None))
[2024-07-17T09:49:55.379+0000] {hive.py:609} DEBUG - TCloseOperationResp(status=TStatus(statusCode=0, infoMessages=None, sqlState=None, errorCode=None, errorMessage=None))
[2024-07-17T09:49:55.379+0000] {hive.py:475} INFO - LOAD DATA LOCAL INPATH '/tmp/test_table.csv' INTO TABLE my_table
[2024-07-17T09:49:55.380+0000] {hive.py:479} DEBUG - TExecuteStatementReq(sessionHandle=TSessionHandle(sessionId=THandleIdentifier(guid=b'\xaam\xc7\x9a\x96\xccNt\xaf03\x9d6\x85R\x15', secret=b'~D\xe4]\xbc\xeb@\xbf\x95\xaeC\xc0DI\xe6\x15')), statement="LOAD DATA LOCAL INPATH '/tmp/test_table.csv' INTO TABLE my_table", confOverlay=None, runAsync=False, queryTimeout=0)
[2024-07-17T09:49:55.407+0000] {hive.py:609} DEBUG - TExecuteStatementResp(status=TStatus(statusCode=3, infoMessages=["*org.apache.hive.service.cli.HiveSQLException:Error while compiling statement: FAILED: SemanticException Line 1:23 Invalid path ''/tmp/test_table.csv'': No files matching path file:/tmp/test_table.csv:17:16", 'org.apache.hive.service.cli.operation.Operation:toSQLException:Operation.java:380', 'org.apache.hive.service.cli.operation.SQLOperation:prepare:SQLOperation.java:206', 'org.apache.hive.service.cli.operation.SQLOperation:runInternal:SQLOperation.java:290', 'org.apache.hive.service.cli.operation.Operation:run:Operation.java:320', 'org.apache.hive.service.cli.session.HiveSessionImpl:executeStatementInternal:HiveSessionImpl.java:530', 'org.apache.hive.service.cli.session.HiveSessionImpl:executeStatement:HiveSessionImpl.java:506', 'org.apache.hive.service.cli.CLIService:executeStatement:CLIService.java:280', 'org.apache.hive.service.cli.thrift.ThriftCLIService:ExecuteStatement:ThriftCLIService.java:531', 'org.apache.hive.service.rpc.thrift.TCLIService$Processor$ExecuteStatement:getResult:TCLIService.java:1437', 'org.apache.hive.service.rpc.thrift.TCLIService$Processor$ExecuteStatement:getResult:TCLIService.java:1422', 'org.apache.thrift.ProcessFunction:process:ProcessFunction.java:39', 'org.apache.thrift.TBaseProcessor:process:TBaseProcessor.java:39', 'org.apache.hive.service.auth.TSetIpAddressProcessor:process:TSetIpAddressProcessor.java:56', 'org.apache.thrift.server.TThreadPoolServer$WorkerProcess:run:TThreadPoolServer.java:286', 'java.util.concurrent.ThreadPoolExecutor:runWorker:ThreadPoolExecutor.java:1142', 'java.util.concurrent.ThreadPoolExecutor$Worker:run:ThreadPoolExecutor.java:617', 'java.lang.Thread:run:Thread.java:748', "*org.apache.hadoop.hive.ql.parse.SemanticException:Line 1:23 Invalid path ''/tmp/test_table.csv'': No files matching path file:/tmp/test_table.csv:22:6", 'org.apache.hadoop.hive.ql.parse.LoadSemanticAnalyzer:applyConstraintsAndGetFiles:LoadSemanticAnalyzer.java:151', 'org.apache.hadoop.hive.ql.parse.LoadSemanticAnalyzer:analyzeInternal:LoadSemanticAnalyzer.java:230', 'org.apache.hadoop.hive.ql.parse.BaseSemanticAnalyzer:analyze:BaseSemanticAnalyzer.java:258', 'org.apache.hadoop.hive.ql.Driver:compile:Driver.java:512', 'org.apache.hadoop.hive.ql.Driver:compileInternal:Driver.java:1317', 'org.apache.hadoop.hive.ql.Driver:compileAndRespond:Driver.java:1295', 'org.apache.hive.service.cli.operation.SQLOperation:prepare:SQLOperation.java:204'], sqlState='42000', errorCode=40000, errorMessage="Error while compiling statement: FAILED: SemanticException Line 1:23 Invalid path ''/tmp/test_table.csv'': No files matching path file:/tmp/test_table.csv"), operationHandle=None)
[2024-07-17T09:49:55.408+0000] {taskinstance.py:2728} ERROR - Task failed with exception
Traceback (most recent call last):
  File "/home/airflow/.local/lib/python3.10/site-packages/airflow/models/taskinstance.py", line 444, in _execute_task
    result = _execute_callable(context=context, **execute_callable_kwargs)
  File "/home/airflow/.local/lib/python3.10/site-packages/airflow/models/taskinstance.py", line 414, in _execute_callable
    return execute_callable(context=context, **execute_callable_kwargs)
  File "/home/airflow/.local/lib/python3.10/site-packages/airflow/operators/python.py", line 200, in execute
    return_value = self.execute_callable()
  File "/home/airflow/.local/lib/python3.10/site-packages/airflow/operators/python.py", line 217, in execute_callable
    return self.python_callable(*self.op_args, **self.op_kwargs)
  File "/opt/airflow/dags/new.py", line 39, in load_data_into_hive
    cursor.execute("LOAD DATA LOCAL INPATH '/tmp/test_table.csv' INTO TABLE my_table")
  File "/home/airflow/.local/lib/python3.10/site-packages/pyhive/hive.py", line 481, in execute
    _check_status(response)
  File "/home/airflow/.local/lib/python3.10/site-packages/pyhive/hive.py", line 611, in _check_status
    raise OperationalError(response)
pyhive.exc.OperationalError: TExecuteStatementResp(status=TStatus(statusCode=3, infoMessages=["*org.apache.hive.service.cli.HiveSQLException:Error while compiling statement: FAILED: SemanticException Line 1:23 Invalid path ''/tmp/test_table.csv'': No files matching path file:/tmp/test_table.csv:17:16", 'org.apache.hive.service.cli.operation.Operation:toSQLException:Operation.java:380', 'org.apache.hive.service.cli.operation.SQLOperation:prepare:SQLOperation.java:206', 'org.apache.hive.service.cli.operation.SQLOperation:runInternal:SQLOperation.java:290', 'org.apache.hive.service.cli.operation.Operation:run:Operation.java:320', 'org.apache.hive.service.cli.session.HiveSessionImpl:executeStatementInternal:HiveSessionImpl.java:530', 'org.apache.hive.service.cli.session.HiveSessionImpl:executeStatement:HiveSessionImpl.java:506', 'org.apache.hive.service.cli.CLIService:executeStatement:CLIService.java:280', 'org.apache.hive.service.cli.thrift.ThriftCLIService:ExecuteStatement:ThriftCLIService.java:531', 'org.apache.hive.service.rpc.thrift.TCLIService$Processor$ExecuteStatement:getResult:TCLIService.java:1437', 'org.apache.hive.service.rpc.thrift.TCLIService$Processor$ExecuteStatement:getResult:TCLIService.java:1422', 'org.apache.thrift.ProcessFunction:process:ProcessFunction.java:39', 'org.apache.thrift.TBaseProcessor:process:TBaseProcessor.java:39', 'org.apache.hive.service.auth.TSetIpAddressProcessor:process:TSetIpAddressProcessor.java:56', 'org.apache.thrift.server.TThreadPoolServer$WorkerProcess:run:TThreadPoolServer.java:286', 'java.util.concurrent.ThreadPoolExecutor:runWorker:ThreadPoolExecutor.java:1142', 'java.util.concurrent.ThreadPoolExecutor$Worker:run:ThreadPoolExecutor.java:617', 'java.lang.Thread:run:Thread.java:748', "*org.apache.hadoop.hive.ql.parse.SemanticException:Line 1:23 Invalid path ''/tmp/test_table.csv'': No files matching path file:/tmp/test_table.csv:22:6", 'org.apache.hadoop.hive.ql.parse.LoadSemanticAnalyzer:applyConstraintsAndGetFiles:LoadSemanticAnalyzer.java:151', 'org.apache.hadoop.hive.ql.parse.LoadSemanticAnalyzer:analyzeInternal:LoadSemanticAnalyzer.java:230', 'org.apache.hadoop.hive.ql.parse.BaseSemanticAnalyzer:analyze:BaseSemanticAnalyzer.java:258', 'org.apache.hadoop.hive.ql.Driver:compile:Driver.java:512', 'org.apache.hadoop.hive.ql.Driver:compileInternal:Driver.java:1317', 'org.apache.hadoop.hive.ql.Driver:compileAndRespond:Driver.java:1295', 'org.apache.hive.service.cli.operation.SQLOperation:prepare:SQLOperation.java:204'], sqlState='42000', errorCode=40000, errorMessage="Error while compiling statement: FAILED: SemanticException Line 1:23 Invalid path ''/tmp/test_table.csv'': No files matching path file:/tmp/test_table.csv"), operationHandle=None)
[2024-07-17T09:49:55.421+0000] {taskinstance.py:527} DEBUG - Task Duration set to 0.576429
[2024-07-17T09:49:55.422+0000] {taskinstance.py:549} DEBUG - Clearing next_method and next_kwargs.
[2024-07-17T09:49:55.423+0000] {taskinstance.py:1149} INFO - Marking task as UP_FOR_RETRY. dag_id=hive_etl, task_id=load_data_into_hive, execution_date=20240717T094917, start_date=20240717T094954, end_date=20240717T094955
[2024-07-17T09:49:55.443+0000] {cli_action_loggers.py:85} DEBUG - Calling callbacks: []
[2024-07-17T09:49:55.444+0000] {standard_task_runner.py:107} ERROR - Failed to execute job 1924 for task load_data_into_hive (TExecuteStatementResp(status=TStatus(statusCode=3, infoMessages=["*org.apache.hive.service.cli.HiveSQLException:Error while compiling statement: FAILED: SemanticException Line 1:23 Invalid path ''/tmp/test_table.csv'': No files matching path file:/tmp/test_table.csv:17:16", 'org.apache.hive.service.cli.operation.Operation:toSQLException:Operation.java:380', 'org.apache.hive.service.cli.operation.SQLOperation:prepare:SQLOperation.java:206', 'org.apache.hive.service.cli.operation.SQLOperation:runInternal:SQLOperation.java:290', 'org.apache.hive.service.cli.operation.Operation:run:Operation.java:320', 'org.apache.hive.service.cli.session.HiveSessionImpl:executeStatementInternal:HiveSessionImpl.java:530', 'org.apache.hive.service.cli.session.HiveSessionImpl:executeStatement:HiveSessionImpl.java:506', 'org.apache.hive.service.cli.CLIService:executeStatement:CLIService.java:280', 'org.apache.hive.service.cli.thrift.ThriftCLIService:ExecuteStatement:ThriftCLIService.java:531', 'org.apache.hive.service.rpc.thrift.TCLIService$Processor$ExecuteStatement:getResult:TCLIService.java:1437', 'org.apache.hive.service.rpc.thrift.TCLIService$Processor$ExecuteStatement:getResult:TCLIService.java:1422', 'org.apache.thrift.ProcessFunction:process:ProcessFunction.java:39', 'org.apache.thrift.TBaseProcessor:process:TBaseProcessor.java:39', 'org.apache.hive.service.auth.TSetIpAddressProcessor:process:TSetIpAddressProcessor.java:56', 'org.apache.thrift.server.TThreadPoolServer$WorkerProcess:run:TThreadPoolServer.java:286', 'java.util.concurrent.ThreadPoolExecutor:runWorker:ThreadPoolExecutor.java:1142', 'java.util.concurrent.ThreadPoolExecutor$Worker:run:ThreadPoolExecutor.java:617', 'java.lang.Thread:run:Thread.java:748', "*org.apache.hadoop.hive.ql.parse.SemanticException:Line 1:23 Invalid path ''/tmp/test_table.csv'': No files matching path file:/tmp/test_table.csv:22:6", 'org.apache.hadoop.hive.ql.parse.LoadSemanticAnalyzer:applyConstraintsAndGetFiles:LoadSemanticAnalyzer.java:151', 'org.apache.hadoop.hive.ql.parse.LoadSemanticAnalyzer:analyzeInternal:LoadSemanticAnalyzer.java:230', 'org.apache.hadoop.hive.ql.parse.BaseSemanticAnalyzer:analyze:BaseSemanticAnalyzer.java:258', 'org.apache.hadoop.hive.ql.Driver:compile:Driver.java:512', 'org.apache.hadoop.hive.ql.Driver:compileInternal:Driver.java:1317', 'org.apache.hadoop.hive.ql.Driver:compileAndRespond:Driver.java:1295', 'org.apache.hive.service.cli.operation.SQLOperation:prepare:SQLOperation.java:204'], sqlState='42000', errorCode=40000, errorMessage="Error while compiling statement: FAILED: SemanticException Line 1:23 Invalid path ''/tmp/test_table.csv'': No files matching path file:/tmp/test_table.csv"), operationHandle=None); 467)
[2024-07-17T09:49:55.467+0000] {local_task_job_runner.py:234} INFO - Task exited with return code 1
[2024-07-17T09:49:55.493+0000] {dagrun.py:876} DEBUG - number of tis tasks for <DagRun hive_etl @ 2024-07-17 09:49:17.873510+00:00: manual__2024-07-17T09:49:17.873510+00:00, state:running, queued_at: 2024-07-17 09:49:17.883620+00:00. externally triggered: True>: 2 task(s)
[2024-07-17T09:49:55.494+0000] {dagrun.py:897} DEBUG - number of scheduleable tasks for <DagRun hive_etl @ 2024-07-17 09:49:17.873510+00:00: manual__2024-07-17T09:49:17.873510+00:00, state:running, queued_at: 2024-07-17 09:49:17.883620+00:00. externally triggered: True>: 2 task(s)
[2024-07-17T09:49:55.495+0000] {taskinstance.py:1988} DEBUG - <TaskInstance: hive_etl.end manual__2024-07-17T09:49:17.873510+00:00 [None]> dependency 'Trigger Rule' PASSED: False, Task's trigger rule 'all_success' requires all upstream tasks to have succeeded, but found 1 non-success(es). upstream_states=_UpstreamTIStates(success=0, skipped=0, failed=0, upstream_failed=0, removed=0, done=0, success_setup=0, skipped_setup=0), upstream_task_ids={'load_data_into_hive'}
[2024-07-17T09:49:55.496+0000] {taskinstance.py:1969} DEBUG - Dependencies not met for <TaskInstance: hive_etl.end manual__2024-07-17T09:49:17.873510+00:00 [None]>, dependency 'Trigger Rule' FAILED: Task's trigger rule 'all_success' requires all upstream tasks to have succeeded, but found 1 non-success(es). upstream_states=_UpstreamTIStates(success=0, skipped=0, failed=0, upstream_failed=0, removed=0, done=0, success_setup=0, skipped_setup=0), upstream_task_ids={'load_data_into_hive'}
[2024-07-17T09:49:55.496+0000] {taskinstance.py:1988} DEBUG - <TaskInstance: hive_etl.end manual__2024-07-17T09:49:17.873510+00:00 [None]> dependency 'Previous Dagrun State' PASSED: True, The task did not have depends_on_past set.
[2024-07-17T09:49:55.496+0000] {taskinstance.py:1988} DEBUG - <TaskInstance: hive_etl.end manual__2024-07-17T09:49:17.873510+00:00 [None]> dependency 'Not In Retry Period' PASSED: True, The task instance was not marked for retrying.
[2024-07-17T09:49:55.497+0000] {taskinstance.py:1988} DEBUG - <TaskInstance: hive_etl.load_data_into_hive manual__2024-07-17T09:49:17.873510+00:00 [up_for_retry]> dependency 'Trigger Rule' PASSED: True, The task instance did not have any upstream tasks.
[2024-07-17T09:49:55.499+0000] {taskinstance.py:1988} DEBUG - <TaskInstance: hive_etl.load_data_into_hive manual__2024-07-17T09:49:17.873510+00:00 [up_for_retry]> dependency 'Previous Dagrun State' PASSED: True, The task did not have depends_on_past set.
[2024-07-17T09:49:55.500+0000] {taskinstance.py:1988} DEBUG - <TaskInstance: hive_etl.load_data_into_hive manual__2024-07-17T09:49:17.873510+00:00 [up_for_retry]> dependency 'Not In Retry Period' PASSED: False, Task is not ready for retry yet but will be retried automatically. Current date is 2024-07-17T09:49:55.500127+00:00 and task will be retried at 2024-07-17T09:54:55.421105+00:00.
[2024-07-17T09:49:55.500+0000] {taskinstance.py:1969} DEBUG - Dependencies not met for <TaskInstance: hive_etl.load_data_into_hive manual__2024-07-17T09:49:17.873510+00:00 [up_for_retry]>, dependency 'Not In Retry Period' FAILED: Task is not ready for retry yet but will be retried automatically. Current date is 2024-07-17T09:49:55.500127+00:00 and task will be retried at 2024-07-17T09:54:55.421105+00:00.
[2024-07-17T09:49:55.516+0000] {taskinstance.py:3309} INFO - 0 downstream tasks scheduled from follow-on schedule check
