[2024-07-17T08:57:02.555+0000] {taskinstance.py:991} DEBUG - previous_execution_date was called
[2024-07-17T08:57:02.577+0000] {__init__.py:54} DEBUG - Loading core task runner: StandardTaskRunner
[2024-07-17T08:57:02.615+0000] {taskinstance.py:991} DEBUG - previous_execution_date was called
[2024-07-17T08:57:02.625+0000] {base_task_runner.py:72} DEBUG - Planning to run as the  user
[2024-07-17T08:57:02.681+0000] {taskinstance.py:1988} DEBUG - <TaskInstance: hive_etl.create_hive_table scheduled__2023-01-22T00:00:00+00:00 [queued]> dependency 'Task Instance State' PASSED: True, Task state queued was valid.
[2024-07-17T08:57:02.682+0000] {taskinstance.py:1988} DEBUG - <TaskInstance: hive_etl.create_hive_table scheduled__2023-01-22T00:00:00+00:00 [queued]> dependency 'Previous Dagrun State' PASSED: True, The task did not have depends_on_past set.
[2024-07-17T08:57:02.696+0000] {taskinstance.py:1988} DEBUG - <TaskInstance: hive_etl.create_hive_table scheduled__2023-01-22T00:00:00+00:00 [queued]> dependency 'Task Instance Not Running' PASSED: True, Task is not in running state.
[2024-07-17T08:57:02.696+0000] {taskinstance.py:1988} DEBUG - <TaskInstance: hive_etl.create_hive_table scheduled__2023-01-22T00:00:00+00:00 [queued]> dependency 'Not In Retry Period' PASSED: True, The task instance was not marked for retrying.
[2024-07-17T08:57:02.697+0000] {taskinstance.py:1979} INFO - Dependencies all met for dep_context=non-requeueable deps ti=<TaskInstance: hive_etl.create_hive_table scheduled__2023-01-22T00:00:00+00:00 [queued]>
[2024-07-17T08:57:02.697+0000] {taskinstance.py:1988} DEBUG - <TaskInstance: hive_etl.create_hive_table scheduled__2023-01-22T00:00:00+00:00 [queued]> dependency 'Previous Dagrun State' PASSED: True, The task did not have depends_on_past set.
[2024-07-17T08:57:02.711+0000] {taskinstance.py:1988} DEBUG - <TaskInstance: hive_etl.create_hive_table scheduled__2023-01-22T00:00:00+00:00 [queued]> dependency 'Pool Slots Available' PASSED: True, There are enough open slots in default_pool to execute the task
[2024-07-17T08:57:02.716+0000] {taskinstance.py:1988} DEBUG - <TaskInstance: hive_etl.create_hive_table scheduled__2023-01-22T00:00:00+00:00 [queued]> dependency 'Task Concurrency' PASSED: True, Task concurrency is not set.
[2024-07-17T08:57:02.717+0000] {taskinstance.py:1988} DEBUG - <TaskInstance: hive_etl.create_hive_table scheduled__2023-01-22T00:00:00+00:00 [queued]> dependency 'Not In Retry Period' PASSED: True, The task instance was not marked for retrying.
[2024-07-17T08:57:02.717+0000] {taskinstance.py:1979} INFO - Dependencies all met for dep_context=requeueable deps ti=<TaskInstance: hive_etl.create_hive_table scheduled__2023-01-22T00:00:00+00:00 [queued]>
[2024-07-17T08:57:02.718+0000] {taskinstance.py:2193} INFO - Starting attempt 1 of 2
[2024-07-17T08:57:02.745+0000] {taskinstance.py:2214} INFO - Executing <Task(PythonOperator): create_hive_table> on 2023-01-22 00:00:00+00:00
[2024-07-17T08:57:02.760+0000] {standard_task_runner.py:60} INFO - Started process 164 to run task
[2024-07-17T08:57:02.767+0000] {standard_task_runner.py:87} INFO - Running: ['***', 'tasks', 'run', 'hive_etl', 'create_hive_table', 'scheduled__2023-01-22T00:00:00+00:00', '--job-id', '1500', '--raw', '--subdir', 'DAGS_FOLDER/new.py', '--cfg-path', '/tmp/tmpbo2i2n67']
[2024-07-17T08:57:02.769+0000] {standard_task_runner.py:88} INFO - Job 1500: Subtask create_hive_table
[2024-07-17T08:57:02.770+0000] {cli_action_loggers.py:67} DEBUG - Calling callbacks: [<function default_action_log at 0x75fe52c56f80>]
[2024-07-17T08:57:02.865+0000] {taskinstance.py:991} DEBUG - previous_execution_date was called
[2024-07-17T08:57:02.871+0000] {task_command.py:423} INFO - Running <TaskInstance: hive_etl.create_hive_table scheduled__2023-01-22T00:00:00+00:00 [running]> on host a88c97f6715f
[2024-07-17T08:57:02.871+0000] {settings.py:386} DEBUG - Disposing DB connection pool (PID 164)
[2024-07-17T08:57:02.872+0000] {settings.py:249} DEBUG - Setting up DB connection pool (PID 164)
[2024-07-17T08:57:02.872+0000] {settings.py:318} DEBUG - settings.prepare_engine_args(): Using NullPool
[2024-07-17T08:57:02.922+0000] {taskinstance.py:991} DEBUG - previous_execution_date was called
[2024-07-17T08:57:02.924+0000] {taskinstance.py:1769} DEBUG - Clearing XCom data
[2024-07-17T08:57:02.931+0000] {retries.py:93} DEBUG - Running RenderedTaskInstanceFields.write with retries. Try 1 of 3
[2024-07-17T08:57:02.961+0000] {retries.py:93} DEBUG - Running RenderedTaskInstanceFields._do_delete_old_records with retries. Try 1 of 3
[2024-07-17T08:57:02.975+0000] {taskinstance.py:2510} INFO - Exporting env vars: AIRFLOW_CTX_DAG_OWNER='***' AIRFLOW_CTX_DAG_ID='hive_etl' AIRFLOW_CTX_TASK_ID='create_hive_table' AIRFLOW_CTX_EXECUTION_DATE='2023-01-22T00:00:00+00:00' AIRFLOW_CTX_TRY_NUMBER='1' AIRFLOW_CTX_DAG_RUN_ID='scheduled__2023-01-22T00:00:00+00:00'
[2024-07-17T08:57:02.976+0000] {__init__.py:115} DEBUG - Preparing lineage inlets and outlets
[2024-07-17T08:57:02.977+0000] {__init__.py:154} DEBUG - inlets: [], outlets: []
[2024-07-17T08:57:02.981+0000] {TSocket.py:129} ERROR - failed to resolve sockaddr for namenode:10000
Traceback (most recent call last):
  File "/home/airflow/.local/lib/python3.10/site-packages/thrift/transport/TSocket.py", line 126, in open
    addrs = self._resolveAddr()
  File "/home/airflow/.local/lib/python3.10/site-packages/thrift/transport/TSocket.py", line 37, in _resolveAddr
    return socket.getaddrinfo(self.host,
  File "/usr/local/lib/python3.10/socket.py", line 955, in getaddrinfo
    for res in _socket.getaddrinfo(host, port, family, type, proto, flags):
socket.gaierror: [Errno -3] Temporary failure in name resolution
[2024-07-17T08:57:02.983+0000] {taskinstance.py:2728} ERROR - Task failed with exception
Traceback (most recent call last):
  File "/home/airflow/.local/lib/python3.10/site-packages/thrift/transport/TSocket.py", line 126, in open
    addrs = self._resolveAddr()
  File "/home/airflow/.local/lib/python3.10/site-packages/thrift/transport/TSocket.py", line 37, in _resolveAddr
    return socket.getaddrinfo(self.host,
  File "/usr/local/lib/python3.10/socket.py", line 955, in getaddrinfo
    for res in _socket.getaddrinfo(host, port, family, type, proto, flags):
socket.gaierror: [Errno -3] Temporary failure in name resolution

During handling of the above exception, another exception occurred:

Traceback (most recent call last):
  File "/home/airflow/.local/lib/python3.10/site-packages/airflow/models/taskinstance.py", line 444, in _execute_task
    result = _execute_callable(context=context, **execute_callable_kwargs)
  File "/home/airflow/.local/lib/python3.10/site-packages/airflow/models/taskinstance.py", line 414, in _execute_callable
    return execute_callable(context=context, **execute_callable_kwargs)
  File "/home/airflow/.local/lib/python3.10/site-packages/airflow/operators/python.py", line 200, in execute
    return_value = self.execute_callable()
  File "/home/airflow/.local/lib/python3.10/site-packages/airflow/operators/python.py", line 217, in execute_callable
    return self.python_callable(*self.op_args, **self.op_kwargs)
  File "/opt/airflow/dags/new.py", line 23, in create_hive_table
    conn = hive.Connection(host='namenode', port=10000, username='hive')
  File "/home/airflow/.local/lib/python3.10/site-packages/pyhive/hive.py", line 269, in __init__
    self._transport.open()
  File "/home/airflow/.local/lib/python3.10/site-packages/thrift_sasl/__init__.py", line 74, in open
    self._trans.open()
  File "/home/airflow/.local/lib/python3.10/site-packages/thrift/transport/TSocket.py", line 130, in open
    raise TTransportException(type=TTransportException.NOT_OPEN, message=msg, inner=gai)
thrift.transport.TTransport.TTransportException: failed to resolve sockaddr for namenode:10000
[2024-07-17T08:57:02.992+0000] {taskinstance.py:527} DEBUG - Task Duration set to 0.294798
[2024-07-17T08:57:02.993+0000] {taskinstance.py:549} DEBUG - Clearing next_method and next_kwargs.
[2024-07-17T08:57:02.994+0000] {taskinstance.py:1149} INFO - Marking task as UP_FOR_RETRY. dag_id=hive_etl, task_id=create_hive_table, execution_date=20230122T000000, start_date=20240717T085702, end_date=20240717T085702
[2024-07-17T08:57:03.012+0000] {cli_action_loggers.py:85} DEBUG - Calling callbacks: []
[2024-07-17T08:57:03.013+0000] {standard_task_runner.py:107} ERROR - Failed to execute job 1500 for task create_hive_table (failed to resolve sockaddr for namenode:10000; 164)
[2024-07-17T08:57:03.060+0000] {local_task_job_runner.py:234} INFO - Task exited with return code 1
[2024-07-17T08:57:03.201+0000] {dagrun.py:876} DEBUG - number of tis tasks for <DagRun hive_etl @ 2023-01-22 00:00:00+00:00: scheduled__2023-01-22T00:00:00+00:00, state:running, queued_at: 2024-07-17 08:56:55.670389+00:00. externally triggered: False>: 3 task(s)
[2024-07-17T08:57:03.202+0000] {dagrun.py:897} DEBUG - number of scheduleable tasks for <DagRun hive_etl @ 2023-01-22 00:00:00+00:00: scheduled__2023-01-22T00:00:00+00:00, state:running, queued_at: 2024-07-17 08:56:55.670389+00:00. externally triggered: False>: 3 task(s)
[2024-07-17T08:57:03.203+0000] {taskinstance.py:1988} DEBUG - <TaskInstance: hive_etl.create_hive_table scheduled__2023-01-22T00:00:00+00:00 [up_for_retry]> dependency 'Not In Retry Period' PASSED: False, Task is not ready for retry yet but will be retried automatically. Current date is 2024-07-17T08:57:03.203165+00:00 and task will be retried at 2024-07-17T09:02:02.992415+00:00.
[2024-07-17T08:57:03.205+0000] {taskinstance.py:1969} DEBUG - Dependencies not met for <TaskInstance: hive_etl.create_hive_table scheduled__2023-01-22T00:00:00+00:00 [up_for_retry]>, dependency 'Not In Retry Period' FAILED: Task is not ready for retry yet but will be retried automatically. Current date is 2024-07-17T08:57:03.203165+00:00 and task will be retried at 2024-07-17T09:02:02.992415+00:00.
[2024-07-17T08:57:03.205+0000] {taskinstance.py:1988} DEBUG - <TaskInstance: hive_etl.create_hive_table scheduled__2023-01-22T00:00:00+00:00 [up_for_retry]> dependency 'Previous Dagrun State' PASSED: True, The task did not have depends_on_past set.
[2024-07-17T08:57:03.207+0000] {taskinstance.py:1988} DEBUG - <TaskInstance: hive_etl.create_hive_table scheduled__2023-01-22T00:00:00+00:00 [up_for_retry]> dependency 'Trigger Rule' PASSED: True, The task instance did not have any upstream tasks.
[2024-07-17T08:57:03.208+0000] {taskinstance.py:1988} DEBUG - <TaskInstance: hive_etl.load_data_into_hive scheduled__2023-01-22T00:00:00+00:00 [None]> dependency 'Not In Retry Period' PASSED: True, The task instance was not marked for retrying.
[2024-07-17T08:57:03.208+0000] {taskinstance.py:1988} DEBUG - <TaskInstance: hive_etl.load_data_into_hive scheduled__2023-01-22T00:00:00+00:00 [None]> dependency 'Previous Dagrun State' PASSED: True, The task did not have depends_on_past set.
[2024-07-17T08:57:03.209+0000] {taskinstance.py:1988} DEBUG - <TaskInstance: hive_etl.load_data_into_hive scheduled__2023-01-22T00:00:00+00:00 [None]> dependency 'Trigger Rule' PASSED: False, Task's trigger rule 'all_success' requires all upstream tasks to have succeeded, but found 1 non-success(es). upstream_states=_UpstreamTIStates(success=0, skipped=0, failed=0, upstream_failed=0, removed=0, done=0, success_setup=0, skipped_setup=0), upstream_task_ids={'create_hive_table'}
[2024-07-17T08:57:03.209+0000] {taskinstance.py:1969} DEBUG - Dependencies not met for <TaskInstance: hive_etl.load_data_into_hive scheduled__2023-01-22T00:00:00+00:00 [None]>, dependency 'Trigger Rule' FAILED: Task's trigger rule 'all_success' requires all upstream tasks to have succeeded, but found 1 non-success(es). upstream_states=_UpstreamTIStates(success=0, skipped=0, failed=0, upstream_failed=0, removed=0, done=0, success_setup=0, skipped_setup=0), upstream_task_ids={'create_hive_table'}
[2024-07-17T08:57:03.210+0000] {taskinstance.py:1988} DEBUG - <TaskInstance: hive_etl.end scheduled__2023-01-22T00:00:00+00:00 [None]> dependency 'Not In Retry Period' PASSED: True, The task instance was not marked for retrying.
[2024-07-17T08:57:03.210+0000] {taskinstance.py:1988} DEBUG - <TaskInstance: hive_etl.end scheduled__2023-01-22T00:00:00+00:00 [None]> dependency 'Previous Dagrun State' PASSED: True, The task did not have depends_on_past set.
[2024-07-17T08:57:03.210+0000] {taskinstance.py:1988} DEBUG - <TaskInstance: hive_etl.end scheduled__2023-01-22T00:00:00+00:00 [None]> dependency 'Trigger Rule' PASSED: False, Task's trigger rule 'all_success' requires all upstream tasks to have succeeded, but found 1 non-success(es). upstream_states=_UpstreamTIStates(success=0, skipped=0, failed=0, upstream_failed=0, removed=0, done=0, success_setup=0, skipped_setup=0), upstream_task_ids={'load_data_into_hive'}
[2024-07-17T08:57:03.211+0000] {taskinstance.py:1969} DEBUG - Dependencies not met for <TaskInstance: hive_etl.end scheduled__2023-01-22T00:00:00+00:00 [None]>, dependency 'Trigger Rule' FAILED: Task's trigger rule 'all_success' requires all upstream tasks to have succeeded, but found 1 non-success(es). upstream_states=_UpstreamTIStates(success=0, skipped=0, failed=0, upstream_failed=0, removed=0, done=0, success_setup=0, skipped_setup=0), upstream_task_ids={'load_data_into_hive'}
[2024-07-17T08:57:03.221+0000] {taskinstance.py:3309} INFO - 0 downstream tasks scheduled from follow-on schedule check
