[2024-07-17T09:22:56.056+0000] {taskinstance.py:991} DEBUG - previous_execution_date was called
[2024-07-17T09:22:56.063+0000] {__init__.py:54} DEBUG - Loading core task runner: StandardTaskRunner
[2024-07-17T09:22:56.072+0000] {taskinstance.py:991} DEBUG - previous_execution_date was called
[2024-07-17T09:22:56.074+0000] {base_task_runner.py:72} DEBUG - Planning to run as the  user
[2024-07-17T09:22:56.089+0000] {taskinstance.py:1988} DEBUG - <TaskInstance: hive_etl.load_data_into_hive scheduled__2023-02-27T00:00:00+00:00 [queued]> dependency 'Not In Retry Period' PASSED: True, The task instance was not marked for retrying.
[2024-07-17T09:22:56.089+0000] {taskinstance.py:1988} DEBUG - <TaskInstance: hive_etl.load_data_into_hive scheduled__2023-02-27T00:00:00+00:00 [queued]> dependency 'Task Instance State' PASSED: True, Task state queued was valid.
[2024-07-17T09:22:56.089+0000] {taskinstance.py:1988} DEBUG - <TaskInstance: hive_etl.load_data_into_hive scheduled__2023-02-27T00:00:00+00:00 [queued]> dependency 'Task Instance Not Running' PASSED: True, Task is not in running state.
[2024-07-17T09:22:56.094+0000] {taskinstance.py:1988} DEBUG - <TaskInstance: hive_etl.load_data_into_hive scheduled__2023-02-27T00:00:00+00:00 [queued]> dependency 'Previous Dagrun State' PASSED: True, The task did not have depends_on_past set.
[2024-07-17T09:22:56.095+0000] {taskinstance.py:1979} INFO - Dependencies all met for dep_context=non-requeueable deps ti=<TaskInstance: hive_etl.load_data_into_hive scheduled__2023-02-27T00:00:00+00:00 [queued]>
[2024-07-17T09:22:56.095+0000] {taskinstance.py:1988} DEBUG - <TaskInstance: hive_etl.load_data_into_hive scheduled__2023-02-27T00:00:00+00:00 [queued]> dependency 'Not In Retry Period' PASSED: True, The task instance was not marked for retrying.
[2024-07-17T09:22:56.098+0000] {taskinstance.py:1988} DEBUG - <TaskInstance: hive_etl.load_data_into_hive scheduled__2023-02-27T00:00:00+00:00 [queued]> dependency 'Pool Slots Available' PASSED: True, There are enough open slots in default_pool to execute the task
[2024-07-17T09:22:56.100+0000] {taskinstance.py:1988} DEBUG - <TaskInstance: hive_etl.load_data_into_hive scheduled__2023-02-27T00:00:00+00:00 [queued]> dependency 'Task Concurrency' PASSED: True, Task concurrency is not set.
[2024-07-17T09:22:56.102+0000] {taskinstance.py:1988} DEBUG - <TaskInstance: hive_etl.load_data_into_hive scheduled__2023-02-27T00:00:00+00:00 [queued]> dependency 'Previous Dagrun State' PASSED: True, The task did not have depends_on_past set.
[2024-07-17T09:22:56.102+0000] {taskinstance.py:1979} INFO - Dependencies all met for dep_context=requeueable deps ti=<TaskInstance: hive_etl.load_data_into_hive scheduled__2023-02-27T00:00:00+00:00 [queued]>
[2024-07-17T09:22:56.102+0000] {taskinstance.py:2193} INFO - Starting attempt 2 of 2
[2024-07-17T09:22:56.112+0000] {taskinstance.py:2214} INFO - Executing <Task(PythonOperator): load_data_into_hive> on 2023-02-27 00:00:00+00:00
[2024-07-17T09:22:56.117+0000] {standard_task_runner.py:60} INFO - Started process 860 to run task
[2024-07-17T09:22:56.119+0000] {standard_task_runner.py:87} INFO - Running: ['***', 'tasks', 'run', 'hive_etl', 'load_data_into_hive', 'scheduled__2023-02-27T00:00:00+00:00', '--job-id', '1699', '--raw', '--subdir', 'DAGS_FOLDER/new.py', '--cfg-path', '/tmp/tmpbhlj9eox']
[2024-07-17T09:22:56.120+0000] {standard_task_runner.py:88} INFO - Job 1699: Subtask load_data_into_hive
[2024-07-17T09:22:56.121+0000] {cli_action_loggers.py:67} DEBUG - Calling callbacks: [<function default_action_log at 0x799cf7552f80>]
[2024-07-17T09:22:56.151+0000] {taskinstance.py:991} DEBUG - previous_execution_date was called
[2024-07-17T09:22:56.153+0000] {task_command.py:423} INFO - Running <TaskInstance: hive_etl.load_data_into_hive scheduled__2023-02-27T00:00:00+00:00 [running]> on host a88c97f6715f
[2024-07-17T09:22:56.153+0000] {settings.py:386} DEBUG - Disposing DB connection pool (PID 860)
[2024-07-17T09:22:56.153+0000] {settings.py:249} DEBUG - Setting up DB connection pool (PID 860)
[2024-07-17T09:22:56.153+0000] {settings.py:318} DEBUG - settings.prepare_engine_args(): Using NullPool
[2024-07-17T09:22:56.177+0000] {taskinstance.py:991} DEBUG - previous_execution_date was called
[2024-07-17T09:22:56.178+0000] {taskinstance.py:1769} DEBUG - Clearing XCom data
[2024-07-17T09:22:56.181+0000] {retries.py:93} DEBUG - Running RenderedTaskInstanceFields.write with retries. Try 1 of 3
[2024-07-17T09:22:56.196+0000] {retries.py:93} DEBUG - Running RenderedTaskInstanceFields._do_delete_old_records with retries. Try 1 of 3
[2024-07-17T09:22:56.204+0000] {taskinstance.py:2510} INFO - Exporting env vars: AIRFLOW_CTX_DAG_OWNER='***' AIRFLOW_CTX_DAG_ID='hive_etl' AIRFLOW_CTX_TASK_ID='load_data_into_hive' AIRFLOW_CTX_EXECUTION_DATE='2023-02-27T00:00:00+00:00' AIRFLOW_CTX_TRY_NUMBER='2' AIRFLOW_CTX_DAG_RUN_ID='scheduled__2023-02-27T00:00:00+00:00'
[2024-07-17T09:22:56.204+0000] {__init__.py:115} DEBUG - Preparing lineage inlets and outlets
[2024-07-17T09:22:56.205+0000] {__init__.py:154} DEBUG - inlets: [], outlets: []
[2024-07-17T09:22:56.206+0000] {TSocket.py:145} INFO - Could not connect to ('172.16.9.72', 10000)
Traceback (most recent call last):
  File "/home/airflow/.local/lib/python3.10/site-packages/thrift/transport/TSocket.py", line 140, in open
    handle.connect(sockaddr)
ConnectionRefusedError: [Errno 111] Connection refused
[2024-07-17T09:22:56.207+0000] {TSocket.py:148} ERROR - Could not connect to any of [('172.16.9.72', 10000)]
[2024-07-17T09:22:56.207+0000] {taskinstance.py:2728} ERROR - Task failed with exception
Traceback (most recent call last):
  File "/home/airflow/.local/lib/python3.10/site-packages/airflow/models/taskinstance.py", line 444, in _execute_task
    result = _execute_callable(context=context, **execute_callable_kwargs)
  File "/home/airflow/.local/lib/python3.10/site-packages/airflow/models/taskinstance.py", line 414, in _execute_callable
    return execute_callable(context=context, **execute_callable_kwargs)
  File "/home/airflow/.local/lib/python3.10/site-packages/airflow/operators/python.py", line 200, in execute
    return_value = self.execute_callable()
  File "/home/airflow/.local/lib/python3.10/site-packages/airflow/operators/python.py", line 217, in execute_callable
    return self.python_callable(*self.op_args, **self.op_kwargs)
  File "/opt/airflow/dags/new.py", line 37, in load_data_into_hive
    conn = hive.Connection(host='172.16.9.72', port=10000, username='hive')
  File "/home/airflow/.local/lib/python3.10/site-packages/pyhive/hive.py", line 269, in __init__
    self._transport.open()
  File "/home/airflow/.local/lib/python3.10/site-packages/thrift_sasl/__init__.py", line 74, in open
    self._trans.open()
  File "/home/airflow/.local/lib/python3.10/site-packages/thrift/transport/TSocket.py", line 149, in open
    raise TTransportException(type=TTransportException.NOT_OPEN, message=msg)
thrift.transport.TTransport.TTransportException: Could not connect to any of [('172.16.9.72', 10000)]
[2024-07-17T09:22:56.212+0000] {taskinstance.py:527} DEBUG - Task Duration set to 0.117534
[2024-07-17T09:22:56.213+0000] {taskinstance.py:549} DEBUG - Clearing next_method and next_kwargs.
[2024-07-17T09:22:56.213+0000] {taskinstance.py:1149} INFO - Marking task as FAILED. dag_id=hive_etl, task_id=load_data_into_hive, execution_date=20230227T000000, start_date=20240717T092256, end_date=20240717T092256
[2024-07-17T09:22:56.221+0000] {cli_action_loggers.py:85} DEBUG - Calling callbacks: []
[2024-07-17T09:22:56.222+0000] {standard_task_runner.py:107} ERROR - Failed to execute job 1699 for task load_data_into_hive (Could not connect to any of [('172.16.9.72', 10000)]; 860)
[2024-07-17T09:22:56.251+0000] {local_task_job_runner.py:234} INFO - Task exited with return code 1
[2024-07-17T09:22:56.263+0000] {dagrun.py:876} DEBUG - number of tis tasks for <DagRun hive_etl @ 2023-02-27 00:00:00+00:00: scheduled__2023-02-27T00:00:00+00:00, state:running, queued_at: 2024-07-17 09:12:45.168841+00:00. externally triggered: False>: 2 task(s)
[2024-07-17T09:22:56.264+0000] {dagrun.py:897} DEBUG - number of scheduleable tasks for <DagRun hive_etl @ 2023-02-27 00:00:00+00:00: scheduled__2023-02-27T00:00:00+00:00, state:running, queued_at: 2024-07-17 09:12:45.168841+00:00. externally triggered: False>: 1 task(s)
[2024-07-17T09:22:56.264+0000] {taskinstance.py:1988} DEBUG - <TaskInstance: hive_etl.end scheduled__2023-02-27T00:00:00+00:00 [None]> dependency 'Not In Retry Period' PASSED: True, The task instance was not marked for retrying.
[2024-07-17T09:22:56.264+0000] {taskinstance.py:1800} DEBUG - Setting task state for <TaskInstance: hive_etl.end scheduled__2023-02-27T00:00:00+00:00 [None]> to upstream_failed
[2024-07-17T09:22:56.264+0000] {taskinstance.py:1988} DEBUG - <TaskInstance: hive_etl.end scheduled__2023-02-27T00:00:00+00:00 [upstream_failed]> dependency 'Trigger Rule' PASSED: False, Task's trigger rule 'all_success' requires all upstream tasks to have succeeded, but found 1 non-success(es). upstream_states=_UpstreamTIStates(success=0, skipped=0, failed=1, upstream_failed=0, removed=0, done=1, success_setup=0, skipped_setup=0), upstream_task_ids={'load_data_into_hive'}
[2024-07-17T09:22:56.265+0000] {taskinstance.py:1969} DEBUG - Dependencies not met for <TaskInstance: hive_etl.end scheduled__2023-02-27T00:00:00+00:00 [upstream_failed]>, dependency 'Trigger Rule' FAILED: Task's trigger rule 'all_success' requires all upstream tasks to have succeeded, but found 1 non-success(es). upstream_states=_UpstreamTIStates(success=0, skipped=0, failed=1, upstream_failed=0, removed=0, done=1, success_setup=0, skipped_setup=0), upstream_task_ids={'load_data_into_hive'}
[2024-07-17T09:22:56.265+0000] {taskinstance.py:1988} DEBUG - <TaskInstance: hive_etl.end scheduled__2023-02-27T00:00:00+00:00 [upstream_failed]> dependency 'Previous Dagrun State' PASSED: True, The task did not have depends_on_past set.
[2024-07-17T09:22:56.268+0000] {taskinstance.py:3309} INFO - 0 downstream tasks scheduled from follow-on schedule check
